
2024-03-07 14:02:02,425 - Mail to manager send successfully
2024-03-07 14:02:02,673 - Mail to client send successfully to human.coin.order@gmail.com
2024-03-07 14:02:40,886 - /home/a/deco_dj/orders/views.py changed, reloading.
2024-03-07 14:02:52,504 - /home/a/deco_dj/orders/views.py changed, reloading.
2024-03-07 14:03:18,255 - /home/a/deco_dj/orders/views.py changed, reloading.
2024-03-07 14:03:22,707 - Mail to manager send successfully
2024-03-07 14:03:23,697 - Error sending mail to human.coin.order@gmail.com
2024-03-07 14:03:46,464 - /home/a/deco_dj/orders/views.py changed, reloading.
2024-03-07 14:03:56,160 - Mail to manager send successfully
2024-03-07 14:03:56,822 - Mail to client send successfully to human.coin.order@gmail.com
2024-03-07 14:13:59,916 - /home/a/deco_dj/freee_dj/settings/base.py changed, reloading.
2024-03-07 14:14:14,467 - /home/a/deco_dj/orders/views.py changed, reloading.
2024-03-07 14:15:56,258 - Internal Server Error: /orders/create/
Traceback (most recent call last):
  File "/home/a/.local/lib/python3.10/site-packages/django/core/handlers/exception.py", line 56, in inner
    response = get_response(request)
  File "/home/a/.local/lib/python3.10/site-packages/django/core/handlers/base.py", line 197, in _get_response
    response = wrapped_callback(request, *callback_args, **callback_kwargs)
  File "/home/a/deco_dj/orders/views.py", line 37, in order_create
    send_mail('Test Email', 'This is a test email message.', 'to.the.neizvestnost@yandex.ru', [order.email])
  File "/home/a/.local/lib/python3.10/site-packages/django/core/mail/__init__.py", line 87, in send_mail
    return mail.send()
  File "/home/a/.local/lib/python3.10/site-packages/django/core/mail/message.py", line 298, in send
    return self.get_connection(fail_silently).send_messages([self])
  File "/home/a/.local/lib/python3.10/site-packages/django/core/mail/backends/smtp.py", line 124, in send_messages
    new_conn_created = self.open()
  File "/home/a/.local/lib/python3.10/site-packages/django/core/mail/backends/smtp.py", line 91, in open
    self.connection.login(self.username, self.password)
  File "/usr/lib/python3.10/smtplib.py", line 750, in login
    raise last_exception
  File "/usr/lib/python3.10/smtplib.py", line 739, in login
    (code, resp) = self.auth(
  File "/usr/lib/python3.10/smtplib.py", line 662, in auth
    raise SMTPAuthenticationError(code, resp)
smtplib.SMTPAuthenticationError: (535, b'5.7.8 Error: authentication failed: This user does not have access rights to this service 1709820955-tFieCjQl5uQ0')
2024-03-07 14:15:56,479 - Not Found: /favicon.ico
2024-03-07 14:27:21,177 - Not Found: /media/
2024-03-07 14:27:21,213 - Not Found: /media/
2024-03-07 14:27:34,088 - Internal Server Error: /orders/create/
Traceback (most recent call last):
  File "/home/a/.local/lib/python3.10/site-packages/django/core/handlers/exception.py", line 56, in inner
    response = get_response(request)
  File "/home/a/.local/lib/python3.10/site-packages/django/core/handlers/base.py", line 197, in _get_response
    response = wrapped_callback(request, *callback_args, **callback_kwargs)
  File "/home/a/deco_dj/orders/views.py", line 37, in order_create
    send_mail('Test Email', 'This is a test email message.', 'to.the.neizvestnost@yandex.ru', [order.email])
  File "/home/a/.local/lib/python3.10/site-packages/django/core/mail/__init__.py", line 87, in send_mail
    return mail.send()
  File "/home/a/.local/lib/python3.10/site-packages/django/core/mail/message.py", line 298, in send
    return self.get_connection(fail_silently).send_messages([self])
  File "/home/a/.local/lib/python3.10/site-packages/django/core/mail/backends/smtp.py", line 124, in send_messages
    new_conn_created = self.open()
  File "/home/a/.local/lib/python3.10/site-packages/django/core/mail/backends/smtp.py", line 91, in open
    self.connection.login(self.username, self.password)
  File "/usr/lib/python3.10/smtplib.py", line 750, in login
    raise last_exception
  File "/usr/lib/python3.10/smtplib.py", line 739, in login
    (code, resp) = self.auth(
  File "/usr/lib/python3.10/smtplib.py", line 662, in auth
    raise SMTPAuthenticationError(code, resp)
smtplib.SMTPAuthenticationError: (535, b'5.7.8 Error: authentication failed: This user does not have access rights to this service 1709821655-YRirE0CAT8c0')
2024-03-07 14:29:38,062 - /home/a/deco_dj/freee_dj/settings/base.py changed, reloading.
2024-03-07 14:29:51,190 - Internal Server Error: /orders/create/
Traceback (most recent call last):
  File "/home/a/.local/lib/python3.10/site-packages/django/core/handlers/exception.py", line 56, in inner
    response = get_response(request)
  File "/home/a/.local/lib/python3.10/site-packages/django/core/handlers/base.py", line 197, in _get_response
    response = wrapped_callback(request, *callback_args, **callback_kwargs)
  File "/home/a/deco_dj/orders/views.py", line 37, in order_create
    send_mail('Test Email', 'This is a test email message.', 'to.the.neizvestnost@yandex.ru', [order.email])
  File "/home/a/.local/lib/python3.10/site-packages/django/core/mail/__init__.py", line 87, in send_mail
    return mail.send()
  File "/home/a/.local/lib/python3.10/site-packages/django/core/mail/message.py", line 298, in send
    return self.get_connection(fail_silently).send_messages([self])
  File "/home/a/.local/lib/python3.10/site-packages/django/core/mail/backends/smtp.py", line 124, in send_messages
    new_conn_created = self.open()
  File "/home/a/.local/lib/python3.10/site-packages/django/core/mail/backends/smtp.py", line 91, in open
    self.connection.login(self.username, self.password)
  File "/usr/lib/python3.10/smtplib.py", line 750, in login
    raise last_exception
  File "/usr/lib/python3.10/smtplib.py", line 739, in login
    (code, resp) = self.auth(
  File "/usr/lib/python3.10/smtplib.py", line 662, in auth
    raise SMTPAuthenticationError(code, resp)
smtplib.SMTPAuthenticationError: (535, b'5.7.8 Error: authentication failed: Invalid user or password! 1709821792-pTiSmtQl7a60')
2024-03-07 14:29:56,975 - /home/a/deco_dj/freee_dj/settings/base.py changed, reloading.
2024-03-07 14:30:14,663 - /home/a/deco_dj/freee_dj/settings/base.py changed, reloading.
2024-03-07 14:30:18,633 - Internal Server Error: /orders/create/
Traceback (most recent call last):
  File "/home/a/.local/lib/python3.10/site-packages/django/core/handlers/exception.py", line 56, in inner
    response = get_response(request)
  File "/home/a/.local/lib/python3.10/site-packages/django/core/handlers/base.py", line 197, in _get_response
    response = wrapped_callback(request, *callback_args, **callback_kwargs)
  File "/home/a/deco_dj/orders/views.py", line 37, in order_create
    send_mail('Test Email', 'This is a test email message.', 'to.the.neizvestnost@yandex.ru', [order.email])
  File "/home/a/.local/lib/python3.10/site-packages/django/core/mail/__init__.py", line 87, in send_mail
    return mail.send()
  File "/home/a/.local/lib/python3.10/site-packages/django/core/mail/message.py", line 298, in send
    return self.get_connection(fail_silently).send_messages([self])
  File "/home/a/.local/lib/python3.10/site-packages/django/core/mail/backends/smtp.py", line 124, in send_messages
    new_conn_created = self.open()
  File "/home/a/.local/lib/python3.10/site-packages/django/core/mail/backends/smtp.py", line 91, in open
    self.connection.login(self.username, self.password)
  File "/usr/lib/python3.10/smtplib.py", line 750, in login
    raise last_exception
  File "/usr/lib/python3.10/smtplib.py", line 739, in login
    (code, resp) = self.auth(
  File "/usr/lib/python3.10/smtplib.py", line 662, in auth
    raise SMTPAuthenticationError(code, resp)
smtplib.SMTPAuthenticationError: (535, b'5.7.8 Error: authentication failed: Invalid user or password! 1709821819-IUinfsTj3iE0')
2024-03-07 14:30:25,370 - Internal Server Error: /orders/create/
Traceback (most recent call last):
  File "/home/a/.local/lib/python3.10/site-packages/django/core/handlers/exception.py", line 56, in inner
    response = get_response(request)
  File "/home/a/.local/lib/python3.10/site-packages/django/core/handlers/base.py", line 197, in _get_response
    response = wrapped_callback(request, *callback_args, **callback_kwargs)
  File "/home/a/deco_dj/orders/views.py", line 37, in order_create
    send_mail('Test Email', 'This is a test email message.', 'to.the.neizvestnost@yandex.ru', [order.email])
  File "/home/a/.local/lib/python3.10/site-packages/django/core/mail/__init__.py", line 87, in send_mail
    return mail.send()
  File "/home/a/.local/lib/python3.10/site-packages/django/core/mail/message.py", line 298, in send
    return self.get_connection(fail_silently).send_messages([self])
  File "/home/a/.local/lib/python3.10/site-packages/django/core/mail/backends/smtp.py", line 124, in send_messages
    new_conn_created = self.open()
  File "/home/a/.local/lib/python3.10/site-packages/django/core/mail/backends/smtp.py", line 91, in open
    self.connection.login(self.username, self.password)
  File "/usr/lib/python3.10/smtplib.py", line 750, in login
    raise last_exception
  File "/usr/lib/python3.10/smtplib.py", line 739, in login
    (code, resp) = self.auth(
  File "/usr/lib/python3.10/smtplib.py", line 662, in auth
    raise SMTPAuthenticationError(code, resp)
smtplib.SMTPAuthenticationError: (535, b'5.7.8 Error: authentication failed: Invalid user or password! 1709821826-QUiVqxO2GuQ0')
2024-03-07 14:30:38,700 - /home/a/deco_dj/freee_dj/settings/base.py changed, reloading.
2024-03-07 14:30:41,739 - Internal Server Error: /orders/create/
Traceback (most recent call last):
  File "/home/a/.local/lib/python3.10/site-packages/django/core/handlers/exception.py", line 56, in inner
    response = get_response(request)
  File "/home/a/.local/lib/python3.10/site-packages/django/core/handlers/base.py", line 197, in _get_response
    response = wrapped_callback(request, *callback_args, **callback_kwargs)
  File "/home/a/deco_dj/orders/views.py", line 37, in order_create
    send_mail('Test Email', 'This is a test email message.', 'to.the.neizvestnost@yandex.ru', [order.email])
  File "/home/a/.local/lib/python3.10/site-packages/django/core/mail/__init__.py", line 87, in send_mail
    return mail.send()
  File "/home/a/.local/lib/python3.10/site-packages/django/core/mail/message.py", line 298, in send
    return self.get_connection(fail_silently).send_messages([self])
  File "/home/a/.local/lib/python3.10/site-packages/django/core/mail/backends/smtp.py", line 124, in send_messages
    new_conn_created = self.open()
  File "/home/a/.local/lib/python3.10/site-packages/django/core/mail/backends/smtp.py", line 91, in open
    self.connection.login(self.username, self.password)
  File "/usr/lib/python3.10/smtplib.py", line 750, in login
    raise last_exception
  File "/usr/lib/python3.10/smtplib.py", line 739, in login
    (code, resp) = self.auth(
  File "/usr/lib/python3.10/smtplib.py", line 662, in auth
    raise SMTPAuthenticationError(code, resp)
smtplib.SMTPAuthenticationError: (535, b'5.7.8 Error: authentication failed: Invalid user or password! 1709821842-gUiROd1Or4Y0')
2024-03-07 14:30:41,906 - Not Found: /favicon.ico
2024-03-07 14:30:59,571 - /home/a/deco_dj/orders/views.py changed, reloading.
2024-03-07 14:31:02,020 - /home/a/deco_dj/freee_dj/settings/base.py changed, reloading.
2024-03-07 14:31:36,254 - Internal Server Error: /orders/create/
Traceback (most recent call last):
  File "/home/a/.local/lib/python3.10/site-packages/django/core/handlers/exception.py", line 56, in inner
    response = get_response(request)
  File "/home/a/.local/lib/python3.10/site-packages/django/core/handlers/base.py", line 197, in _get_response
    response = wrapped_callback(request, *callback_args, **callback_kwargs)
  File "/home/a/deco_dj/orders/views.py", line 37, in order_create
    send_mail('Test Email', 'This is a test email message.', 'to.the.neizvestnost@yandex.ru', [order.email])
  File "/home/a/.local/lib/python3.10/site-packages/django/core/mail/__init__.py", line 87, in send_mail
    return mail.send()
  File "/home/a/.local/lib/python3.10/site-packages/django/core/mail/message.py", line 298, in send
    return self.get_connection(fail_silently).send_messages([self])
  File "/home/a/.local/lib/python3.10/site-packages/django/core/mail/backends/smtp.py", line 124, in send_messages
    new_conn_created = self.open()
  File "/home/a/.local/lib/python3.10/site-packages/django/core/mail/backends/smtp.py", line 91, in open
    self.connection.login(self.username, self.password)
  File "/usr/lib/python3.10/smtplib.py", line 750, in login
    raise last_exception
  File "/usr/lib/python3.10/smtplib.py", line 739, in login
    (code, resp) = self.auth(
  File "/usr/lib/python3.10/smtplib.py", line 662, in auth
    raise SMTPAuthenticationError(code, resp)
smtplib.SMTPAuthenticationError: (535, b'5.7.8 Error: authentication failed: Invalid user or password! 1709821897-aVi6lPBf4qM0')
2024-03-07 14:31:51,784 - /home/a/deco_dj/orders/views.py changed, reloading.
2024-03-07 14:31:55,479 - Internal Server Error: /orders/create/
Traceback (most recent call last):
  File "/home/a/.local/lib/python3.10/site-packages/django/core/handlers/exception.py", line 56, in inner
    response = get_response(request)
  File "/home/a/.local/lib/python3.10/site-packages/django/core/handlers/base.py", line 197, in _get_response
    response = wrapped_callback(request, *callback_args, **callback_kwargs)
  File "/home/a/deco_dj/orders/views.py", line 37, in order_create
    send_mail('Test Email', 'This is a test email message.', 'komy.kabachok@yandex.ru', [order.email])
  File "/home/a/.local/lib/python3.10/site-packages/django/core/mail/__init__.py", line 87, in send_mail
    return mail.send()
  File "/home/a/.local/lib/python3.10/site-packages/django/core/mail/message.py", line 298, in send
    return self.get_connection(fail_silently).send_messages([self])
  File "/home/a/.local/lib/python3.10/site-packages/django/core/mail/backends/smtp.py", line 124, in send_messages
    new_conn_created = self.open()
  File "/home/a/.local/lib/python3.10/site-packages/django/core/mail/backends/smtp.py", line 91, in open
    self.connection.login(self.username, self.password)
  File "/usr/lib/python3.10/smtplib.py", line 750, in login
    raise last_exception
  File "/usr/lib/python3.10/smtplib.py", line 739, in login
    (code, resp) = self.auth(
  File "/usr/lib/python3.10/smtplib.py", line 662, in auth
    raise SMTPAuthenticationError(code, resp)
smtplib.SMTPAuthenticationError: (535, b'5.7.8 Error: authentication failed: Invalid user or password! 1709821916-uViqUP2Pi8c0')
2024-03-07 14:32:04,748 - Internal Server Error: /orders/create/
Traceback (most recent call last):
  File "/home/a/.local/lib/python3.10/site-packages/django/core/handlers/exception.py", line 56, in inner
    response = get_response(request)
  File "/home/a/.local/lib/python3.10/site-packages/django/core/handlers/base.py", line 197, in _get_response
    response = wrapped_callback(request, *callback_args, **callback_kwargs)
  File "/home/a/deco_dj/orders/views.py", line 37, in order_create
    send_mail('Test Email', 'This is a test email message.', 'komy.kabachok@yandex.ru', [order.email])
  File "/home/a/.local/lib/python3.10/site-packages/django/core/mail/__init__.py", line 87, in send_mail
    return mail.send()
  File "/home/a/.local/lib/python3.10/site-packages/django/core/mail/message.py", line 298, in send
    return self.get_connection(fail_silently).send_messages([self])
  File "/home/a/.local/lib/python3.10/site-packages/django/core/mail/backends/smtp.py", line 124, in send_messages
    new_conn_created = self.open()
  File "/home/a/.local/lib/python3.10/site-packages/django/core/mail/backends/smtp.py", line 91, in open
    self.connection.login(self.username, self.password)
  File "/usr/lib/python3.10/smtplib.py", line 750, in login
    raise last_exception
  File "/usr/lib/python3.10/smtplib.py", line 739, in login
    (code, resp) = self.auth(
  File "/usr/lib/python3.10/smtplib.py", line 662, in auth
    raise SMTPAuthenticationError(code, resp)
smtplib.SMTPAuthenticationError: (535, b'5.7.8 Error: authentication failed: Invalid user or password! 1709821925-4WiR12CQkGk0')
2024-03-07 14:36:04,233 - Mail to manager send successfully
2024-03-07 14:36:05,146 - Mail to client send successfully to madmarakuya@gmail.com
2024-03-07 14:36:40,154 - /home/a/deco_dj/freee_dj/settings/base.py changed, reloading.
2024-03-07 14:39:22,285 - /home/a/deco_dj/orders/views.py changed, reloading.
2024-03-07 15:22:50,454 - /home/a/deco_dj/orders/models.py changed, reloading.
2024-03-07 15:25:18,377 - /home/a/deco_dj/orders/forms.py changed, reloading.
2024-03-07 15:25:40,022 - /home/a/deco_dj/orders/forms.py changed, reloading.
2024-03-07 15:26:13,909 - /home/a/deco_dj/orders/models.py changed, reloading.
2024-03-07 15:34:46,342 - Not Found: /orders/create/images/CONSONO_ARM_CORSO_08_GOODS_02_G2l7gyn.png
2024-03-07 15:34:46,498 - Not Found: /orders/create/images/CONSONO_ARM_CORSO_08_GOODS_02_G2l7gyn.png
2024-03-07 15:35:00,013 - Not Found: /orders/create/media/images/CONSONO_ARM_CORSO_08_GOODS_02_G2l7gyn.png
2024-03-07 15:35:00,154 - Not Found: /orders/create/media/images/CONSONO_ARM_CORSO_08_GOODS_02_G2l7gyn.png
2024-03-07 15:36:19,021 - Internal Server Error: /orders/create/
Traceback (most recent call last):
  File "/home/a/.local/lib/python3.10/site-packages/django/template/base.py", line 505, in parse
    compile_func = self.tags[command]
KeyError: 'static'

During handling of the above exception, another exception occurred:

Traceback (most recent call last):
  File "/home/a/.local/lib/python3.10/site-packages/django/core/handlers/exception.py", line 56, in inner
    response = get_response(request)
  File "/home/a/.local/lib/python3.10/site-packages/django/core/handlers/base.py", line 197, in _get_response
    response = wrapped_callback(request, *callback_args, **callback_kwargs)
  File "/home/a/deco_dj/orders/views.py", line 76, in order_create
    return render(request, 'orders/order/create.html', {'cart': cart, 'form': form})
  File "/home/a/.local/lib/python3.10/site-packages/django/shortcuts.py", line 24, in render
    content = loader.render_to_string(template_name, context, request, using=using)
  File "/home/a/.local/lib/python3.10/site-packages/django/template/loader.py", line 61, in render_to_string
    template = get_template(template_name, using=using)
  File "/home/a/.local/lib/python3.10/site-packages/django/template/loader.py", line 15, in get_template
    return engine.get_template(template_name)
  File "/home/a/.local/lib/python3.10/site-packages/django/template/backends/django.py", line 33, in get_template
    return Template(self.engine.get_template(template_name), self)
  File "/home/a/.local/lib/python3.10/site-packages/django/template/engine.py", line 175, in get_template
    template, origin = self.find_template(template_name)
  File "/home/a/.local/lib/python3.10/site-packages/django/template/engine.py", line 157, in find_template
    template = loader.get_template(name, skip=skip)
  File "/home/a/.local/lib/python3.10/site-packages/django/template/loaders/cached.py", line 57, in get_template
    template = super().get_template(template_name, skip)
  File "/home/a/.local/lib/python3.10/site-packages/django/template/loaders/base.py", line 28, in get_template
    return Template(
  File "/home/a/.local/lib/python3.10/site-packages/django/template/base.py", line 154, in __init__
    self.nodelist = self.compile_nodelist()
  File "/home/a/.local/lib/python3.10/site-packages/django/template/base.py", line 200, in compile_nodelist
    return parser.parse()
  File "/home/a/.local/lib/python3.10/site-packages/django/template/base.py", line 513, in parse
    raise self.error(token, e)
  File "/home/a/.local/lib/python3.10/site-packages/django/template/base.py", line 511, in parse
    compiled_result = compile_func(self, token)
  File "/home/a/.local/lib/python3.10/site-packages/django/template/loader_tags.py", line 293, in do_extends
    nodelist = parser.parse()
  File "/home/a/.local/lib/python3.10/site-packages/django/template/base.py", line 513, in parse
    raise self.error(token, e)
  File "/home/a/.local/lib/python3.10/site-packages/django/template/base.py", line 511, in parse
    compiled_result = compile_func(self, token)
  File "/home/a/.local/lib/python3.10/site-packages/django/template/loader_tags.py", line 232, in do_block
    nodelist = parser.parse(("endblock",))
  File "/home/a/.local/lib/python3.10/site-packages/django/template/base.py", line 513, in parse
    raise self.error(token, e)
  File "/home/a/.local/lib/python3.10/site-packages/django/template/base.py", line 511, in parse
    compiled_result = compile_func(self, token)
  File "/home/a/.local/lib/python3.10/site-packages/django/template/defaulttags.py", line 853, in do_for
    nodelist_loop = parser.parse(
  File "/home/a/.local/lib/python3.10/site-packages/django/template/base.py", line 513, in parse
    raise self.error(token, e)
  File "/home/a/.local/lib/python3.10/site-packages/django/template/base.py", line 511, in parse
    compiled_result = compile_func(self, token)
  File "/home/a/.local/lib/python3.10/site-packages/django/template/defaulttags.py", line 967, in do_if
    nodelist = parser.parse(("endif",))
  File "/home/a/.local/lib/python3.10/site-packages/django/template/base.py", line 507, in parse
    self.invalid_block_tag(token, command, parse_until)
  File "/home/a/.local/lib/python3.10/site-packages/django/template/base.py", line 558, in invalid_block_tag
    raise self.error(
django.template.exceptions.TemplateSyntaxError: Invalid block tag on line 41: 'static', expected 'endif'. Did you forget to register or load this tag?
2024-03-07 15:36:42,939 - Not Found: /orders/create/media//media/images/CONSONO_ARM_CORSO_08_GOODS_02_G2l7gyn.png
2024-03-07 15:36:43,074 - Not Found: /orders/create/media//media/images/CONSONO_ARM_CORSO_08_GOODS_02_G2l7gyn.png
2024-03-07 15:36:57,964 - Not Found: /orders/create/media//media/images/CONSONO_ARM_CORSO_08_GOODS_02_G2l7gyn.png
2024-03-07 15:36:58,105 - Not Found: /orders/create/media//media/images/CONSONO_ARM_CORSO_08_GOODS_02_G2l7gyn.png
2024-03-07 15:37:57,874 - Not Found: /media/
2024-03-07 15:37:58,017 - Not Found: /media/
2024-03-07 15:53:25,108 - /home/a/deco_dj/orders/forms.py changed, reloading.
2024-03-07 15:55:59,041 - /home/a/deco_dj/orders/forms.py changed, reloading.
2024-03-07 15:56:34,174 - Internal Server Error: /orders/create/
Traceback (most recent call last):
  File "/home/a/.local/lib/python3.10/site-packages/django/core/handlers/exception.py", line 56, in inner
    response = get_response(request)
  File "/home/a/.local/lib/python3.10/site-packages/django/core/handlers/base.py", line 197, in _get_response
    response = wrapped_callback(request, *callback_args, **callback_kwargs)
  File "/home/a/deco_dj/orders/views.py", line 75, in order_create
    form = OrderCreateForm()
  File "/home/a/deco_dj/orders/forms.py", line 11, in __init__
    super(MyForm, self).__init__(*args, **kwargs)
NameError: name 'MyForm' is not defined
2024-03-07 15:56:35,289 - Internal Server Error: /orders/create/
Traceback (most recent call last):
  File "/home/a/.local/lib/python3.10/site-packages/django/core/handlers/exception.py", line 56, in inner
    response = get_response(request)
  File "/home/a/.local/lib/python3.10/site-packages/django/core/handlers/base.py", line 197, in _get_response
    response = wrapped_callback(request, *callback_args, **callback_kwargs)
  File "/home/a/deco_dj/orders/views.py", line 75, in order_create
    form = OrderCreateForm()
  File "/home/a/deco_dj/orders/forms.py", line 11, in __init__
    super(MyForm, self).__init__(*args, **kwargs)
NameError: name 'MyForm' is not defined
2024-03-07 15:56:42,621 - /home/a/deco_dj/orders/forms.py changed, reloading.
2024-03-08 10:05:53,754 - Not Found: /products/consono-arm-jazz-01/image2.jpg
2024-03-08 10:05:53,757 - Not Found: /products/consono-arm-jazz-01/image3.jpg
2024-03-08 10:05:53,762 - Not Found: /products/consono-arm-jazz-01/image1.jpg
2024-03-08 11:43:10,844 - Not Found: /products/consono-mod1-jazz-21/
2024-03-08 11:45:54,146 - /home/a/deco_dj/product/models.py changed, reloading.
2024-03-10 10:12:47,863 - Internal Server Error: /products/consono-arm-jazz-01/
Traceback (most recent call last):
  File "/home/a/.local/lib/python3.10/site-packages/django/template/base.py", line 880, in _resolve_lookup
    current = current[bit]
TypeError: 'FieldFile' object is not subscriptable

During handling of the above exception, another exception occurred:

Traceback (most recent call last):
  File "/home/a/.local/lib/python3.10/site-packages/django/core/handlers/exception.py", line 56, in inner
    response = get_response(request)
  File "/home/a/.local/lib/python3.10/site-packages/django/core/handlers/base.py", line 197, in _get_response
    response = wrapped_callback(request, *callback_args, **callback_kwargs)
  File "/home/a/deco_dj/product/views.py", line 93, in single_product
    return render(request, 'product/single_product.html', {
  File "/home/a/.local/lib/python3.10/site-packages/django/shortcuts.py", line 24, in render
    content = loader.render_to_string(template_name, context, request, using=using)
  File "/home/a/.local/lib/python3.10/site-packages/django/template/loader.py", line 62, in render_to_string
    return template.render(context, request)
  File "/home/a/.local/lib/python3.10/site-packages/django/template/backends/django.py", line 61, in render
    return self.template.render(context)
  File "/home/a/.local/lib/python3.10/site-packages/django/template/base.py", line 175, in render
    return self._render(context)
  File "/home/a/.local/lib/python3.10/site-packages/django/template/base.py", line 167, in _render
    return self.nodelist.render(context)
  File "/home/a/.local/lib/python3.10/site-packages/django/template/base.py", line 1005, in render
    return SafeString("".join([node.render_annotated(context) for node in self]))
  File "/home/a/.local/lib/python3.10/site-packages/django/template/base.py", line 1005, in <listcomp>
    return SafeString("".join([node.render_annotated(context) for node in self]))
  File "/home/a/.local/lib/python3.10/site-packages/django/template/base.py", line 966, in render_annotated
    return self.render(context)
  File "/home/a/.local/lib/python3.10/site-packages/django/template/loader_tags.py", line 157, in render
    return compiled_parent._render(context)
  File "/home/a/.local/lib/python3.10/site-packages/django/template/base.py", line 167, in _render
    return self.nodelist.render(context)
  File "/home/a/.local/lib/python3.10/site-packages/django/template/base.py", line 1005, in render
    return SafeString("".join([node.render_annotated(context) for node in self]))
  File "/home/a/.local/lib/python3.10/site-packages/django/template/base.py", line 1005, in <listcomp>
    return SafeString("".join([node.render_annotated(context) for node in self]))
  File "/home/a/.local/lib/python3.10/site-packages/django/template/base.py", line 966, in render_annotated
    return self.render(context)
  File "/home/a/.local/lib/python3.10/site-packages/django/template/loader_tags.py", line 63, in render
    result = block.nodelist.render(context)
  File "/home/a/.local/lib/python3.10/site-packages/django/template/base.py", line 1005, in render
    return SafeString("".join([node.render_annotated(context) for node in self]))
  File "/home/a/.local/lib/python3.10/site-packages/django/template/base.py", line 1005, in <listcomp>
    return SafeString("".join([node.render_annotated(context) for node in self]))
  File "/home/a/.local/lib/python3.10/site-packages/django/template/base.py", line 966, in render_annotated
    return self.render(context)
  File "/home/a/.local/lib/python3.10/site-packages/django/template/base.py", line 1064, in render
    output = self.filter_expression.resolve(context)
  File "/home/a/.local/lib/python3.10/site-packages/django/template/base.py", line 715, in resolve
    obj = self.var.resolve(context)
  File "/home/a/.local/lib/python3.10/site-packages/django/template/base.py", line 847, in resolve
    value = self._resolve_lookup(context)
  File "/home/a/.local/lib/python3.10/site-packages/django/template/base.py", line 890, in _resolve_lookup
    current = getattr(current, bit)
  File "/home/a/.local/lib/python3.10/site-packages/django/db/models/fields/files.py", line 65, in url
    self._require_file()
  File "/home/a/.local/lib/python3.10/site-packages/django/db/models/fields/files.py", line 40, in _require_file
    raise ValueError(
ValueError: The 'scheme' attribute has no file associated with it.
2024-03-10 10:12:48,021 - Not Found: /favicon.ico
2024-03-10 10:14:57,776 - Not Found: /products/consono-accessory-velutto-32/schemes/inst.svg
2024-03-10 10:37:02,363 - Not Found: /media/
2024-03-10 10:37:04,528 - Internal Server Error: /products/consono-arm-cambridge-600/
Traceback (most recent call last):
  File "/home/a/.local/lib/python3.10/site-packages/django/template/base.py", line 880, in _resolve_lookup
    current = current[bit]
TypeError: 'FieldFile' object is not subscriptable

During handling of the above exception, another exception occurred:

Traceback (most recent call last):
  File "/home/a/.local/lib/python3.10/site-packages/django/core/handlers/exception.py", line 56, in inner
    response = get_response(request)
  File "/home/a/.local/lib/python3.10/site-packages/django/core/handlers/base.py", line 197, in _get_response
    response = wrapped_callback(request, *callback_args, **callback_kwargs)
  File "/home/a/deco_dj/product/views.py", line 93, in single_product
    return render(request, 'product/single_product.html', {
  File "/home/a/.local/lib/python3.10/site-packages/django/shortcuts.py", line 24, in render
    content = loader.render_to_string(template_name, context, request, using=using)
  File "/home/a/.local/lib/python3.10/site-packages/django/template/loader.py", line 62, in render_to_string
    return template.render(context, request)
  File "/home/a/.local/lib/python3.10/site-packages/django/template/backends/django.py", line 61, in render
    return self.template.render(context)
  File "/home/a/.local/lib/python3.10/site-packages/django/template/base.py", line 175, in render
    return self._render(context)
  File "/home/a/.local/lib/python3.10/site-packages/django/template/base.py", line 167, in _render
    return self.nodelist.render(context)
  File "/home/a/.local/lib/python3.10/site-packages/django/template/base.py", line 1005, in render
    return SafeString("".join([node.render_annotated(context) for node in self]))
  File "/home/a/.local/lib/python3.10/site-packages/django/template/base.py", line 1005, in <listcomp>
    return SafeString("".join([node.render_annotated(context) for node in self]))
  File "/home/a/.local/lib/python3.10/site-packages/django/template/base.py", line 966, in render_annotated
    return self.render(context)
  File "/home/a/.local/lib/python3.10/site-packages/django/template/loader_tags.py", line 157, in render
    return compiled_parent._render(context)
  File "/home/a/.local/lib/python3.10/site-packages/django/template/base.py", line 167, in _render
    return self.nodelist.render(context)
  File "/home/a/.local/lib/python3.10/site-packages/django/template/base.py", line 1005, in render
    return SafeString("".join([node.render_annotated(context) for node in self]))
  File "/home/a/.local/lib/python3.10/site-packages/django/template/base.py", line 1005, in <listcomp>
    return SafeString("".join([node.render_annotated(context) for node in self]))
  File "/home/a/.local/lib/python3.10/site-packages/django/template/base.py", line 966, in render_annotated
    return self.render(context)
  File "/home/a/.local/lib/python3.10/site-packages/django/template/loader_tags.py", line 63, in render
    result = block.nodelist.render(context)
  File "/home/a/.local/lib/python3.10/site-packages/django/template/base.py", line 1005, in render
    return SafeString("".join([node.render_annotated(context) for node in self]))
  File "/home/a/.local/lib/python3.10/site-packages/django/template/base.py", line 1005, in <listcomp>
    return SafeString("".join([node.render_annotated(context) for node in self]))
  File "/home/a/.local/lib/python3.10/site-packages/django/template/base.py", line 966, in render_annotated
    return self.render(context)
  File "/home/a/.local/lib/python3.10/site-packages/django/template/base.py", line 1064, in render
    output = self.filter_expression.resolve(context)
  File "/home/a/.local/lib/python3.10/site-packages/django/template/base.py", line 715, in resolve
    obj = self.var.resolve(context)
  File "/home/a/.local/lib/python3.10/site-packages/django/template/base.py", line 847, in resolve
    value = self._resolve_lookup(context)
  File "/home/a/.local/lib/python3.10/site-packages/django/template/base.py", line 890, in _resolve_lookup
    current = getattr(current, bit)
  File "/home/a/.local/lib/python3.10/site-packages/django/db/models/fields/files.py", line 65, in url
    self._require_file()
  File "/home/a/.local/lib/python3.10/site-packages/django/db/models/fields/files.py", line 40, in _require_file
    raise ValueError(
ValueError: The 'scheme' attribute has no file associated with it.
2024-03-10 10:37:04,682 - Not Found: /favicon.ico
2024-03-10 12:09:33,115 - Internal Server Error: /admin/product/product/30/change/
Traceback (most recent call last):
  File "/home/a/.local/lib/python3.10/site-packages/django/contrib/admin/options.py", line 807, in get_form
    return modelform_factory(self.model, **defaults)
  File "/home/a/.local/lib/python3.10/site-packages/django/forms/models.py", line 648, in modelform_factory
    return type(form)(class_name, (form,), form_class_attrs)
  File "/home/a/.local/lib/python3.10/site-packages/django/forms/models.py", line 327, in __new__
    raise FieldError(message)
django.core.exceptions.FieldError: Unknown field(s) (popover_img) specified for Product

During handling of the above exception, another exception occurred:

Traceback (most recent call last):
  File "/home/a/.local/lib/python3.10/site-packages/django/core/handlers/exception.py", line 56, in inner
    response = get_response(request)
  File "/home/a/.local/lib/python3.10/site-packages/django/core/handlers/base.py", line 197, in _get_response
    response = wrapped_callback(request, *callback_args, **callback_kwargs)
  File "/home/a/.local/lib/python3.10/site-packages/django/contrib/admin/options.py", line 686, in wrapper
    return self.admin_site.admin_view(view)(*args, **kwargs)
  File "/home/a/.local/lib/python3.10/site-packages/django/utils/decorators.py", line 134, in _wrapped_view
    response = view_func(request, *args, **kwargs)
  File "/home/a/.local/lib/python3.10/site-packages/django/views/decorators/cache.py", line 62, in _wrapped_view_func
    response = view_func(request, *args, **kwargs)
  File "/home/a/.local/lib/python3.10/site-packages/django/contrib/admin/sites.py", line 242, in inner
    return view(request, *args, **kwargs)
  File "/home/a/.local/lib/python3.10/site-packages/django/contrib/admin/options.py", line 1894, in change_view
    return self.changeform_view(request, object_id, form_url, extra_context)
  File "/home/a/.local/lib/python3.10/site-packages/django/utils/decorators.py", line 46, in _wrapper
    return bound_method(*args, **kwargs)
  File "/home/a/.local/lib/python3.10/site-packages/django/utils/decorators.py", line 134, in _wrapped_view
    response = view_func(request, *args, **kwargs)
  File "/home/a/.local/lib/python3.10/site-packages/django/contrib/admin/options.py", line 1751, in changeform_view
    return self._changeform_view(request, object_id, form_url, extra_context)
  File "/home/a/.local/lib/python3.10/site-packages/django/contrib/admin/options.py", line 1787, in _changeform_view
    ModelForm = self.get_form(
  File "/home/a/.local/lib/python3.10/site-packages/django/contrib/admin/options.py", line 809, in get_form
    raise FieldError(
django.core.exceptions.FieldError: Unknown field(s) (popover_img) specified for Product. Check fields/fieldsets/exclude attributes of class ProductAdmin.
2024-03-10 12:09:33,261 - Not Found: /favicon.ico
2024-03-10 12:09:38,939 - Internal Server Error: /admin/product/product/30/change/
Traceback (most recent call last):
  File "/home/a/.local/lib/python3.10/site-packages/django/contrib/admin/options.py", line 807, in get_form
    return modelform_factory(self.model, **defaults)
  File "/home/a/.local/lib/python3.10/site-packages/django/forms/models.py", line 648, in modelform_factory
    return type(form)(class_name, (form,), form_class_attrs)
  File "/home/a/.local/lib/python3.10/site-packages/django/forms/models.py", line 327, in __new__
    raise FieldError(message)
django.core.exceptions.FieldError: Unknown field(s) (popover_img) specified for Product

During handling of the above exception, another exception occurred:

Traceback (most recent call last):
  File "/home/a/.local/lib/python3.10/site-packages/django/core/handlers/exception.py", line 56, in inner
    response = get_response(request)
  File "/home/a/.local/lib/python3.10/site-packages/django/core/handlers/base.py", line 197, in _get_response
    response = wrapped_callback(request, *callback_args, **callback_kwargs)
  File "/home/a/.local/lib/python3.10/site-packages/django/contrib/admin/options.py", line 686, in wrapper
    return self.admin_site.admin_view(view)(*args, **kwargs)
  File "/home/a/.local/lib/python3.10/site-packages/django/utils/decorators.py", line 134, in _wrapped_view
    response = view_func(request, *args, **kwargs)
  File "/home/a/.local/lib/python3.10/site-packages/django/views/decorators/cache.py", line 62, in _wrapped_view_func
    response = view_func(request, *args, **kwargs)
  File "/home/a/.local/lib/python3.10/site-packages/django/contrib/admin/sites.py", line 242, in inner
    return view(request, *args, **kwargs)
  File "/home/a/.local/lib/python3.10/site-packages/django/contrib/admin/options.py", line 1894, in change_view
    return self.changeform_view(request, object_id, form_url, extra_context)
  File "/home/a/.local/lib/python3.10/site-packages/django/utils/decorators.py", line 46, in _wrapper
    return bound_method(*args, **kwargs)
  File "/home/a/.local/lib/python3.10/site-packages/django/utils/decorators.py", line 134, in _wrapped_view
    response = view_func(request, *args, **kwargs)
  File "/home/a/.local/lib/python3.10/site-packages/django/contrib/admin/options.py", line 1751, in changeform_view
    return self._changeform_view(request, object_id, form_url, extra_context)
  File "/home/a/.local/lib/python3.10/site-packages/django/contrib/admin/options.py", line 1787, in _changeform_view
    ModelForm = self.get_form(
  File "/home/a/.local/lib/python3.10/site-packages/django/contrib/admin/options.py", line 809, in get_form
    raise FieldError(
django.core.exceptions.FieldError: Unknown field(s) (popover_img) specified for Product. Check fields/fieldsets/exclude attributes of class ProductAdmin.
2024-03-10 12:16:58,546 - Internal Server Error: /admin/product/product/21/change/
Traceback (most recent call last):
  File "/home/a/.local/lib/python3.10/site-packages/django/contrib/admin/options.py", line 807, in get_form
    return modelform_factory(self.model, **defaults)
  File "/home/a/.local/lib/python3.10/site-packages/django/forms/models.py", line 648, in modelform_factory
    return type(form)(class_name, (form,), form_class_attrs)
  File "/home/a/.local/lib/python3.10/site-packages/django/forms/models.py", line 327, in __new__
    raise FieldError(message)
django.core.exceptions.FieldError: Unknown field(s) (popover_img) specified for Product

During handling of the above exception, another exception occurred:

Traceback (most recent call last):
  File "/home/a/.local/lib/python3.10/site-packages/django/core/handlers/exception.py", line 56, in inner
    response = get_response(request)
  File "/home/a/.local/lib/python3.10/site-packages/django/core/handlers/base.py", line 197, in _get_response
    response = wrapped_callback(request, *callback_args, **callback_kwargs)
  File "/home/a/.local/lib/python3.10/site-packages/django/contrib/admin/options.py", line 686, in wrapper
    return self.admin_site.admin_view(view)(*args, **kwargs)
  File "/home/a/.local/lib/python3.10/site-packages/django/utils/decorators.py", line 134, in _wrapped_view
    response = view_func(request, *args, **kwargs)
  File "/home/a/.local/lib/python3.10/site-packages/django/views/decorators/cache.py", line 62, in _wrapped_view_func
    response = view_func(request, *args, **kwargs)
  File "/home/a/.local/lib/python3.10/site-packages/django/contrib/admin/sites.py", line 242, in inner
    return view(request, *args, **kwargs)
  File "/home/a/.local/lib/python3.10/site-packages/django/contrib/admin/options.py", line 1894, in change_view
    return self.changeform_view(request, object_id, form_url, extra_context)
  File "/home/a/.local/lib/python3.10/site-packages/django/utils/decorators.py", line 46, in _wrapper
    return bound_method(*args, **kwargs)
  File "/home/a/.local/lib/python3.10/site-packages/django/utils/decorators.py", line 134, in _wrapped_view
    response = view_func(request, *args, **kwargs)
  File "/home/a/.local/lib/python3.10/site-packages/django/contrib/admin/options.py", line 1751, in changeform_view
    return self._changeform_view(request, object_id, form_url, extra_context)
  File "/home/a/.local/lib/python3.10/site-packages/django/contrib/admin/options.py", line 1787, in _changeform_view
    ModelForm = self.get_form(
  File "/home/a/.local/lib/python3.10/site-packages/django/contrib/admin/options.py", line 809, in get_form
    raise FieldError(
django.core.exceptions.FieldError: Unknown field(s) (popover_img) specified for Product. Check fields/fieldsets/exclude attributes of class ProductAdmin.
2024-03-10 12:27:26,150 - /home/a/deco_dj/product/models.py changed, reloading.
2024-03-10 12:37:49,949 - Not Found: /media/
2024-03-10 12:37:50,091 - Not Found: /media/
2024-03-10 12:40:11,850 - Not Found: /media/
2024-03-13 21:24:37,300 - Not Found: /products/consono-accessory-pixel-forest/
2024-03-13 21:24:37,487 - Not Found: /favicon.ico
2024-03-13 21:28:44,091 - Not Found: /products/consono-arm-velutto-32/
2024-03-13 21:28:51,924 - Not Found: /media/
2024-03-13 21:28:55,365 - Not Found: /products/consono-arm-pixel-forest/
2024-03-13 21:29:03,416 - Not Found: /products/consono-arm-velutto-32/
2024-03-13 21:29:33,001 - /home/a/deco_dj/product/models.py changed, reloading.
2024-03-14 13:02:32,007 - /home/a/deco_dj/freee_dj/settings/base.py changed, reloading.
2024-03-14 13:02:51,710 - /home/a/deco_dj/freee_dj/settings/base.py changed, reloading.
2024-03-14 13:03:07,332 - /home/a/deco_dj/freee_dj/settings/base.py changed, reloading.
2024-03-14 13:03:10,817 - /home/a/deco_dj/freee_dj/settings/base.py changed, reloading.
2024-03-14 13:03:29,508 - /home/a/deco_dj/orders/views.py changed, reloading.
2024-03-14 13:03:54,508 - Mail to manager send successfully
2024-03-14 13:03:54,592 - Mail to client send successfully to human.coin.order@gmail.com
2024-03-14 13:14:44,954 - /home/a/deco_dj/freee_dj/settings/base.py changed, reloading.
2024-03-14 13:14:50,458 - /home/a/deco_dj/freee_dj/settings/base.py changed, reloading.
2024-03-14 13:14:55,087 - Not Found: /media/pages_hats/delivery_hat.jpg
2024-03-14 13:14:55,171 - Not Found: /media/pages_hats/delivery_hat.jpg
2024-03-14 13:15:03,963 - Not Found: /media/
2024-03-14 13:15:04,101 - Not Found: /media/
2024-03-14 13:15:27,678 - Mail to manager send successfully
2024-03-14 13:15:28,431 - Mail to client send successfully to human.coin.order@gmail.com
2024-03-14 13:19:04,441 - /home/a/deco_dj/freee_dj/settings/base.py changed, reloading.
2024-03-14 13:19:12,072 - /home/a/deco_dj/freee_dj/settings/base.py changed, reloading.
2024-03-14 13:19:16,767 - Not Found: /media/
2024-03-14 13:19:16,897 - Not Found: /media/
2024-03-14 13:19:39,538 - Mail to manager send successfully
2024-03-14 13:19:42,384 - Mail to client send successfully to human.coin.order@gmail.com
2024-03-14 13:20:02,824 - /home/a/deco_dj/freee_dj/settings/base.py changed, reloading.
2024-03-14 13:24:40,356 - /home/a/deco_dj/freee_dj/settings/base.py changed, reloading.
2024-03-14 13:24:58,989 - Not Found: /media/
2024-03-14 13:24:59,112 - Not Found: /media/
2024-03-14 13:25:16,691 - Not Found: /products/consono-arm-pixel-forest/
2024-03-14 13:25:16,924 - Not Found: /favicon.ico
2024-03-14 13:25:31,463 - Not Found: /products/consono-mod1-jazz-21/
2024-03-14 13:26:34,584 - Mail to manager send successfully
2024-03-14 13:26:37,365 - Mail to client send successfully to human.coin.order@gmail.com
2024-03-14 13:28:12,946 - /home/a/deco_dj/freee_dj/settings/base.py changed, reloading.
2024-03-14 13:28:21,511 - /home/a/deco_dj/orders/views.py changed, reloading.
2024-03-14 13:28:29,225 - Not Found: /media/
2024-03-14 13:28:29,361 - Not Found: /media/
2024-03-14 13:28:47,997 - Mail to manager send successfully
2024-03-14 13:28:51,052 - Mail to client send successfully to human.coin.order@gmail.com
2024-03-14 13:31:30,626 - /home/a/deco_dj/freee_dj/settings/base.py changed, reloading.
2024-03-14 13:31:49,145 - Not Found: /media/
2024-03-14 13:31:49,277 - Not Found: /media/
2024-03-14 13:32:18,002 - Mail to manager send successfully
2024-03-14 13:32:20,778 - Mail to client send successfully to komy.kabachok@yandex.ru
2024-03-14 13:35:26,912 - /home/a/deco_dj/freee_dj/settings/base.py changed, reloading.
2024-03-14 13:35:43,595 - Not Found: /media/
2024-03-14 13:35:43,728 - Not Found: /media/
2024-03-14 13:35:58,998 - Mail to manager send successfully
2024-03-14 13:35:59,082 - Mail to client send successfully to komy.kabachok@yandex.ru
2024-03-14 13:37:31,895 - /home/a/deco_dj/freee_dj/settings/base.py changed, reloading.
2024-03-14 13:38:12,020 - /home/a/deco_dj/freee_dj/settings/base.py changed, reloading.
2024-03-14 13:38:31,793 - /home/a/deco_dj/freee_dj/settings/base.py changed, reloading.
2024-03-14 13:38:41,396 - /home/a/deco_dj/orders/views.py changed, reloading.
2024-03-14 13:39:29,218 - Mail to manager send successfully
2024-03-14 13:39:31,891 - Mail to client send successfully to komy.kabachok@yandex.ru
2024-03-14 13:44:45,738 - /home/a/deco_dj/freee_dj/settings/base.py changed, reloading.
2024-03-14 13:46:02,478 - /home/a/deco_dj/freee_dj/settings/base.py changed, reloading.
2024-03-14 13:46:41,503 - /home/a/deco_dj/orders/views.py changed, reloading.
2024-03-14 13:46:53,024 - /home/a/deco_dj/orders/views.py changed, reloading.
2024-03-14 13:47:38,215 - /home/a/deco_dj/freee_dj/settings/base.py changed, reloading.
2024-03-14 13:47:47,777 - /home/a/deco_dj/freee_dj/settings/base.py changed, reloading.
2024-03-14 13:47:54,174 - /home/a/deco_dj/freee_dj/settings/base.py changed, reloading.
2024-03-14 13:50:06,921 - /home/a/deco_dj/freee_dj/settings/base.py changed, reloading.
2024-03-14 13:54:12,319 - Mail to manager send successfully
2024-03-14 13:54:14,981 - Mail to client send successfully to komy.kabachok@yandex.ru
2024-03-14 13:54:49,961 - /home/a/deco_dj/freee_dj/settings/base.py changed, reloading.
2024-03-14 13:55:37,106 - Not Found: /media/
2024-03-14 13:55:52,503 - Mail to manager send successfully
2024-03-14 13:55:53,135 - Mail to client send successfully to komy.kabachok@yandex.ru
2024-03-14 13:56:19,228 - /home/a/deco_dj/freee_dj/settings/base.py changed, reloading.
2024-03-14 14:01:03,402 - /home/a/deco_dj/freee_dj/settings/base.py changed, reloading.
2024-03-14 14:05:49,832 - /home/a/deco_dj/freee_dj/settings/base.py changed, reloading.
2024-03-14 14:06:25,455 - Mail to manager send successfully
2024-03-14 14:06:28,170 - Mail to client send successfully to komy.kabachok@yandex.ru
2024-03-14 15:47:47,164 - /home/a/deco_dj/product/models.py changed, reloading.
2024-03-14 23:20:06,212 - Internal Server Error: /admin/product/product/add/
Traceback (most recent call last):
  File "/home/a/.local/lib/python3.10/site-packages/django/db/backends/utils.py", line 89, in _execute
    return self.cursor.execute(sql, params)
  File "/home/a/.local/lib/python3.10/site-packages/django/db/backends/sqlite3/base.py", line 357, in execute
    return Database.Cursor.execute(self, query, params)
sqlite3.IntegrityError: NOT NULL constraint failed: product_product.price

The above exception was the direct cause of the following exception:

Traceback (most recent call last):
  File "/home/a/.local/lib/python3.10/site-packages/django/core/handlers/exception.py", line 56, in inner
    response = get_response(request)
  File "/home/a/.local/lib/python3.10/site-packages/django/core/handlers/base.py", line 197, in _get_response
    response = wrapped_callback(request, *callback_args, **callback_kwargs)
  File "/home/a/.local/lib/python3.10/site-packages/django/contrib/admin/options.py", line 686, in wrapper
    return self.admin_site.admin_view(view)(*args, **kwargs)
  File "/home/a/.local/lib/python3.10/site-packages/django/utils/decorators.py", line 134, in _wrapped_view
    response = view_func(request, *args, **kwargs)
  File "/home/a/.local/lib/python3.10/site-packages/django/views/decorators/cache.py", line 62, in _wrapped_view_func
    response = view_func(request, *args, **kwargs)
  File "/home/a/.local/lib/python3.10/site-packages/django/contrib/admin/sites.py", line 242, in inner
    return view(request, *args, **kwargs)
  File "/home/a/.local/lib/python3.10/site-packages/django/contrib/admin/options.py", line 1891, in add_view
    return self.changeform_view(request, None, form_url, extra_context)
  File "/home/a/.local/lib/python3.10/site-packages/django/utils/decorators.py", line 46, in _wrapper
    return bound_method(*args, **kwargs)
  File "/home/a/.local/lib/python3.10/site-packages/django/utils/decorators.py", line 134, in _wrapped_view
    response = view_func(request, *args, **kwargs)
  File "/home/a/.local/lib/python3.10/site-packages/django/contrib/admin/options.py", line 1751, in changeform_view
    return self._changeform_view(request, object_id, form_url, extra_context)
  File "/home/a/.local/lib/python3.10/site-packages/django/contrib/admin/options.py", line 1803, in _changeform_view
    self.save_model(request, new_object, form, not add)
  File "/home/a/.local/lib/python3.10/site-packages/django/contrib/admin/options.py", line 1226, in save_model
    obj.save()
  File "/home/a/deco_dj/product/models.py", line 356, in save
    super().save(*args, **kwargs)
  File "/home/a/.local/lib/python3.10/site-packages/django/db/models/base.py", line 812, in save
    self.save_base(
  File "/home/a/.local/lib/python3.10/site-packages/django/db/models/base.py", line 863, in save_base
    updated = self._save_table(
  File "/home/a/.local/lib/python3.10/site-packages/django/db/models/base.py", line 1006, in _save_table
    results = self._do_insert(
  File "/home/a/.local/lib/python3.10/site-packages/django/db/models/base.py", line 1047, in _do_insert
    return manager._insert(
  File "/home/a/.local/lib/python3.10/site-packages/django/db/models/manager.py", line 85, in manager_method
    return getattr(self.get_queryset(), name)(*args, **kwargs)
  File "/home/a/.local/lib/python3.10/site-packages/django/db/models/query.py", line 1791, in _insert
    return query.get_compiler(using=using).execute_sql(returning_fields)
  File "/home/a/.local/lib/python3.10/site-packages/django/db/models/sql/compiler.py", line 1660, in execute_sql
    cursor.execute(sql, params)
  File "/home/a/.local/lib/python3.10/site-packages/django/db/backends/utils.py", line 102, in execute
    return super().execute(sql, params)
  File "/home/a/.local/lib/python3.10/site-packages/django/db/backends/utils.py", line 67, in execute
    return self._execute_with_wrappers(
  File "/home/a/.local/lib/python3.10/site-packages/django/db/backends/utils.py", line 80, in _execute_with_wrappers
    return executor(sql, params, many, context)
  File "/home/a/.local/lib/python3.10/site-packages/django/db/backends/utils.py", line 84, in _execute
    with self.db.wrap_database_errors:
  File "/home/a/.local/lib/python3.10/site-packages/django/db/utils.py", line 91, in __exit__
    raise dj_exc_value.with_traceback(traceback) from exc_value
  File "/home/a/.local/lib/python3.10/site-packages/django/db/backends/utils.py", line 89, in _execute
    return self.cursor.execute(sql, params)
  File "/home/a/.local/lib/python3.10/site-packages/django/db/backends/sqlite3/base.py", line 357, in execute
    return Database.Cursor.execute(self, query, params)
django.db.utils.IntegrityError: NOT NULL constraint failed: product_product.price
2024-03-14 23:20:06,396 - Not Found: /favicon.ico
2024-03-14 23:20:53,645 - Internal Server Error: /admin/product/product/add/
Traceback (most recent call last):
  File "/home/a/.local/lib/python3.10/site-packages/django/db/backends/utils.py", line 89, in _execute
    return self.cursor.execute(sql, params)
  File "/home/a/.local/lib/python3.10/site-packages/django/db/backends/sqlite3/base.py", line 357, in execute
    return Database.Cursor.execute(self, query, params)
sqlite3.IntegrityError: NOT NULL constraint failed: product_product.popover_id

The above exception was the direct cause of the following exception:

Traceback (most recent call last):
  File "/home/a/.local/lib/python3.10/site-packages/django/core/handlers/exception.py", line 56, in inner
    response = get_response(request)
  File "/home/a/.local/lib/python3.10/site-packages/django/core/handlers/base.py", line 197, in _get_response
    response = wrapped_callback(request, *callback_args, **callback_kwargs)
  File "/home/a/.local/lib/python3.10/site-packages/django/contrib/admin/options.py", line 686, in wrapper
    return self.admin_site.admin_view(view)(*args, **kwargs)
  File "/home/a/.local/lib/python3.10/site-packages/django/utils/decorators.py", line 134, in _wrapped_view
    response = view_func(request, *args, **kwargs)
  File "/home/a/.local/lib/python3.10/site-packages/django/views/decorators/cache.py", line 62, in _wrapped_view_func
    response = view_func(request, *args, **kwargs)
  File "/home/a/.local/lib/python3.10/site-packages/django/contrib/admin/sites.py", line 242, in inner
    return view(request, *args, **kwargs)
  File "/home/a/.local/lib/python3.10/site-packages/django/contrib/admin/options.py", line 1891, in add_view
    return self.changeform_view(request, None, form_url, extra_context)
  File "/home/a/.local/lib/python3.10/site-packages/django/utils/decorators.py", line 46, in _wrapper
    return bound_method(*args, **kwargs)
  File "/home/a/.local/lib/python3.10/site-packages/django/utils/decorators.py", line 134, in _wrapped_view
    response = view_func(request, *args, **kwargs)
  File "/home/a/.local/lib/python3.10/site-packages/django/contrib/admin/options.py", line 1751, in changeform_view
    return self._changeform_view(request, object_id, form_url, extra_context)
  File "/home/a/.local/lib/python3.10/site-packages/django/contrib/admin/options.py", line 1803, in _changeform_view
    self.save_model(request, new_object, form, not add)
  File "/home/a/.local/lib/python3.10/site-packages/django/contrib/admin/options.py", line 1226, in save_model
    obj.save()
  File "/home/a/deco_dj/product/models.py", line 356, in save
    super().save(*args, **kwargs)
  File "/home/a/.local/lib/python3.10/site-packages/django/db/models/base.py", line 812, in save
    self.save_base(
  File "/home/a/.local/lib/python3.10/site-packages/django/db/models/base.py", line 863, in save_base
    updated = self._save_table(
  File "/home/a/.local/lib/python3.10/site-packages/django/db/models/base.py", line 1006, in _save_table
    results = self._do_insert(
  File "/home/a/.local/lib/python3.10/site-packages/django/db/models/base.py", line 1047, in _do_insert
    return manager._insert(
  File "/home/a/.local/lib/python3.10/site-packages/django/db/models/manager.py", line 85, in manager_method
    return getattr(self.get_queryset(), name)(*args, **kwargs)
  File "/home/a/.local/lib/python3.10/site-packages/django/db/models/query.py", line 1791, in _insert
    return query.get_compiler(using=using).execute_sql(returning_fields)
  File "/home/a/.local/lib/python3.10/site-packages/django/db/models/sql/compiler.py", line 1660, in execute_sql
    cursor.execute(sql, params)
  File "/home/a/.local/lib/python3.10/site-packages/django/db/backends/utils.py", line 102, in execute
    return super().execute(sql, params)
  File "/home/a/.local/lib/python3.10/site-packages/django/db/backends/utils.py", line 67, in execute
    return self._execute_with_wrappers(
  File "/home/a/.local/lib/python3.10/site-packages/django/db/backends/utils.py", line 80, in _execute_with_wrappers
    return executor(sql, params, many, context)
  File "/home/a/.local/lib/python3.10/site-packages/django/db/backends/utils.py", line 84, in _execute
    with self.db.wrap_database_errors:
  File "/home/a/.local/lib/python3.10/site-packages/django/db/utils.py", line 91, in __exit__
    raise dj_exc_value.with_traceback(traceback) from exc_value
  File "/home/a/.local/lib/python3.10/site-packages/django/db/backends/utils.py", line 89, in _execute
    return self.cursor.execute(sql, params)
  File "/home/a/.local/lib/python3.10/site-packages/django/db/backends/sqlite3/base.py", line 357, in execute
    return Database.Cursor.execute(self, query, params)
django.db.utils.IntegrityError: NOT NULL constraint failed: product_product.popover_id
2024-03-15 00:39:25,389 - Not Found: /media/
2024-03-15 00:39:35,275 - Not Found: /categories/corner/
2024-03-15 00:39:35,422 - Not Found: /favicon.ico
2024-03-15 00:39:42,451 - Not Found: /favicon.ico
2024-03-15 00:39:57,699 - Not Found: /media/
2024-03-15 00:40:02,310 - Not Found: /favicon.ico
2024-03-15 00:40:03,085 - Not Found: /categories/corner/
2024-03-15 00:40:56,178 - Not Found: /media/
2024-03-15 00:40:56,329 - Not Found: /media/
